Workbook

Sheet Dashboard
B2: Restaurant Delivery Performance Dashboard
B3: Sample data: 300 orders, Jan-Mar 2026, 11 cities, 22 restaurants
B6: Delivery Success Rate
B7: =Analysis!A143 -> 0.73

Sheet Orders
A1: OrderID | B1: City | C1: OrderDate | D1: DeliveryStatus | E1: OrderAmount | F1: CustomerName | G1: Phone | H1: CustomerID | I1: RestaurantID | J1: RestaurantName | K1: Cuisine
A2: ORD1020 | B2: Mumbai | C2: 46023 | D2: Delivered | E2: 607.33 | F2: Pooja Iyer | G2: 9876543221 | H2: C012 | I2: R004 | J2: =INDEX(Restaurants!$B$2:$B$23,MATCH(I2,Restaurants!$A$2:$A$23,0)) -> Sea Breeze Grill | K2: =INDEX(Restaurants!$D$2:$D$23,MATCH(I2,Restaurants!$A$2:$A$23,0)) -> Seafood
A3: ORD1134 | B3: Hyderabad | C3: 46023 | D3: Delivered | E3: 579.35 | F3: Nikhil Jain | G3: 9876543224 | H3: C015 | I3: R010 | J3: =INDEX(Restaurants!$B$2:$B$23,MATCH(I3,Restaurants!$A$2:$A$23,0)) -> Nizam's Table | K3: =INDEX(Restaurants!$D$2:$D$23,MATCH(I3,Restaurants!$A$2:$A$23,0)) -> Mughlai
A4: ORD1137 | B4: Ahmedabad | C4: 46023 | D4: Delivered | E4: 417.23 | F4: Sneha Patel | G4: 9876543215 | H4: C006 | I4: R011 | J4: =INDEX(Restaurants!$B$2:$B$23,MATCH(I4,Restaurants!$A$2:$A$23,0)) -> Gujarat Thali Home | K4: =INDEX(Restaurants!$D$2:$D$23,MATCH(I4,Restaurants!$A$2:$A$23,0)) -> Gujarati
A5: ORD1256 | B5: Bangalore | C5: 46023 | D5: Out for Delivery | E5: 386.08 | F5: Aman Verma | G5: 9876543212 | H5: C003 | I5: R006 | J5: =INDEX(Restaurants!$B$2:$B$23,MATCH(I5,Restaurants!$A$2:$A$23,0)) -> Silicon Spice | K5: =INDEX(Restaurants!$D$2:$D$23,MATCH(I5,Restaurants!$A$2:$A$23,0)) -> Multi-Cuisine
A6: ORD1294 | B6: Hyderabad | C6: 46023 | D6: Delivered | E6: 545.14 | F6: Arjun Mehta | G6: 9876543214 | H6: C005 | I6: R010 | J6: =INDEX(Restaurants!$B$2:$B$23,MATCH(I6,Restaurants!$A$2:$A$23,0)) -> Nizam's Table | K6: =INDEX(Restaurants!$D$2:$D$23,MATCH(I6,Restaurants!$A$2:$A$23,0)) -> Mughlai
A7: ORD1019 | B7: Mumbai | C7: 46024 | D7: Cancelled | E7: 1027.72 | F7: Priya Singh | G7: 9876543211 | H7: C002 | I7: R003 | J7: =INDEX(Restaurants!$B$2:$B$23,MATCH(I7,Restaurants!$A$2:$A$23,0)) -> Bombay Bites | K7: =INDEX(Restaurants!$D$2:$D$23,MATCH(I7,Restaurants!$A$2:$A$23,0)) -> Street Food
A8: ORD1104 | B8: Lucknow | C8: 46024 | D8: Cancelled | E8: 241.87 | F8: Harsh Vardhan | G8: 9876543234 | H8: C025 | I8: R019 | J8: =INDEX(Restaurants!$B$2:$B$23,MATCH(I8,Restaurants!$A$2:$A$23,0)) -> Tunday Kababi Corner | K8: =INDEX(Restaurants!$D$2:$D$23,MATCH(I8,Restaurants!$A$2:$A$23,0)) -> Awadhi
A9: ORD1091 | B9: Kochi | C9: 46025 | D9: Delivered | E9: 490.33 | F9: Kavya Nair | G9: 9876543217 | H9: C008 | I9: R016 | J9: =INDEX(Restaurants!$B$2:$B$23,MATCH(I9,Restaurants!$A$2:$A$23,0)) -> Fort Kochi Seafoods | K9: =INDEX(Restaurants!$D$2:$D$23,MATCH(I9,Restaurants!$A$2:$A$23,0)) -> Seafood
A10: ORD1129 | B10: Pune | C10: 46025 | D10: Pending | E10: 570.49 | F10: Simran Kaur | G10: 9876543223 | H10: C014 | I10: R007 | J10: =INDEX(Restaurants!$B$2:$B$23,MATCH(I10,Restaurants!$A$2:$A$23,0)) -> Puneri Misal House | K10: =INDEX(Restaurants!$D$2:$D$23,MATCH(I10,Restaurants!$A$2:$A$23,0)) -> Maharashtrian
A11: ORD1274 | B11: Chennai | C11: 46025 | D11: Delivered | E11: 442.36 | F11: Divya Menon | G11: 9876543225 | H11: C016 | I11: R014 | J11: =INDEX(Restaurants!$B$2:$B$23,MATCH(I11,Restaurants!$A$2:$A$23,0)) -> Chettinad Corner | K11: =INDEX(Restaurants!$D$2:$D$23,MATCH(I11,Restaurants!$A$2:$A$23,0)) -> Chettinad
A12: ORD1096 | B12: Kolkata | C12: 46026 | D12: Delivered | E12: 315.76 | F12: Sahil Khan | G12: 9876543226 | H12: C017 | I12: R021 | J12: =INDEX(Restaurants!$B$2:$B$23,MATCH(I12,Restaurants!$A$2:$A$23,0)) -> Bong Bhoj | K12: =INDEX(Restaurants!$D$2:$D$23,MATCH(I12,Restaurants!$A$2:$A$23,0)) -> Bengali
A13: ORD1145 | B13: Pune | C13: 46026 | D13: Delivered | E13: 912.7 | F13: Neha Gupta | G13: 9876543213 | H13: C004 | I13: R008 | J13: =INDEX(Restaurants!$B$2:$B$23,MATCH(I13,Restaurants!$A$2:$A$23,0)) -> Deccan Diner | K13: =INDEX(Restaurants!$D$2:$D$23,MATCH(I13,Restaurants!$A$2:$A$23,0)) -> Continental
... A301: ORD1167 | B301: Ahmedabad | C301: 46112 | D301: Delivered | E301: 1019.21 | F301: Sneha Patel | G301: 9876543215 | H301: C006 | I301: R011 | J301: =INDEX(Restaurants!$B$2:$B$23,MATCH(I301,Restaurants!$A$2:$A$23,0)) -> Gujarat Thali Home | K301: =INDEX(Restaurants!$D$2:$D$23,MATCH(I301,Restaurants!$A$2:$A$23,0)) -> Gujarati

Sheet Customers
A1: CustomerID | B1: CustomerName | C1: Phone | D1: City
A2: C001 | B2: Rahul Sharma | C2: 9876543210 | D2: Delhi
A3: C002 | B3: Priya Singh | C3: 9876543211 | D3: Mumbai
A4: C003 | B4: Aman Verma | C4: 9876543212 | D4: Bangalore
A5: C004 | B5: Neha Gupta | C5: 9876543213 | D5: Pune
A6: C005 | B6: Arjun Mehta | C6: 9876543214 | D6: Hyderabad
A7: C006 | B7: Sneha Patel | C7: 9876543215 | D7: Ahmedabad
A8: C007 | B8: Vikram Rao | C8: 9876543216 | D8: Chennai
A9: C008 | B9: Kavya Nair | C9: 9876543217 | D9: Kochi
A10: C009 | B10: Rohan Kapoor | C10: 9876543218 | D10: Jaipur
A11: C010 | B11: Anjali Joshi | C11: 9876543219 | D11: Lucknow
A12: C011 | B12: Karan Malhotra | C12: 9876543220 | D12: Delhi
... A26: C025 | B26: Harsh Vardhan | C26: 9876543234 | D26: Lucknow

Sheet Restaurants
A1: RestaurantID | B1: RestaurantName | C1: City | D1: Cuisine | E1: Rating | F1: ContactNumber
A2: R001 | B2: Delhi Darbar | C2: Delhi | D2: North Indian | E2: 3.9 | F2: 9876540001
A3: R002 | B3: Karim's Kitchen | C3: Delhi | D3: Mughlai | E3: 3.7 | F3: 9876540002
A4: R003 | B4: Bombay Bites | C4: Mumbai | D4: Street Food | E4: 4.3 | F4: 9876540003
A5: R004 | B5: Sea Breeze Grill | C5: Mumbai | D5: Seafood | E5: 3.6 | F5: 9876540004
A6: R005 | B6: Namma Bangalore Cafe | C6: Bangalore | D6: South Indian | E6: 4.2 | F6: 9876540005
A7: R006 | B7: Silicon Spice | C7: Bangalore | D7: Multi-Cuisine | E7: 4 | F7: 9876540006
A8: R007 | B8: Puneri Misal House | C8: Pune | D8: Maharashtrian | E8: 3.6 | F8: 9876540007
A9: R008 | B9: Deccan Diner | C9: Pune | D9: Continental | E9: 4.2 | F9: 9876540008
A10: R009 | B10: Hyderabadi Biryani House | C10: Hyderabad | D10: Biryani | E10: 3.5 | F10: 9876540009
A11: R010 | B11: Nizam's Table | C11: Hyderabad | D11: Mughlai | E11: 4.1 | F11: 9876540010
A12: R011 | B12: Gujarat Thali Home | C12: Ahmedabad | D12: Gujarati | E12: 3.6 | F12: 9876540011
A13: R012 | B13: Manek Chowk Bites | C13: Ahmedabad | D13: Street Food | E13: 3.6 | F13: 9876540012
... A23: R022 | B23: Park Street Diner | C23: Kolkata | D23: Continental | E23: 3.6 | F23: 9876540022

Sheet Analysis
A1: Total Revenue by Restaurant (Delivered orders)
A2: RestaurantID | B2: RestaurantName | C2: TotalRevenue
A3: =Restaurants!A2 -> R001 | B3: =Restaurants!B2 -> Delhi Darbar | C3: =SUMIFS(Orders!$E$2:$E$301,Orders!$I$2:$I$301,A3,Orders!$D$2:$D$301,"Delivered") -> 12567.69
A4: =Restaurants!A3 -> R002 | B4: =Restaurants!B3 -> Karim's Kitchen | C4: =SUMIFS(Orders!$E$2:$E$301,Orders!$I$2:$I$301,A4,Orders!$D$2:$D$301,"Delivered") -> 13570
A5: =Restaurants!A4 -> R003 | B5: =Restaurants!B4 -> Bombay Bites | C5: =SUMIFS(Orders!$E$2:$E$301,Orders!$I$2:$I$301,A5,Orders!$D$2:$D$301,"Delivered") -> 18514.89
A6: =Restaurants!A5 -> R004 | B6: =Restaurants!B5 -> Sea Breeze Grill | C6: =SUMIFS(Orders!$E$2:$E$301,Orders!$I$2:$I$301,A6,Orders!$D$2:$D$301,"Delivered") -> 12520.9
A7: =Restaurants!A6 -> R005 | B7: =Restaurants!B6 -> Namma Bangalore Cafe | C7: =SUMIFS(Orders!$E$2:$E$301,Orders!$I$2:$I$301,A7,Orders!$D$2:$D$301,"Delivered") -> 5720.3
A8: =Restaurants!A7 -> R006 | B8: =Restaurants!B7 -> Silicon Spice | C8: =SUMIFS(Orders!$E$2:$E$301,Orders!$I$2:$I$301,A8,Orders!$D$2:$D$301,"Delivered") -> 7635.87
A9: =Restaurants!A8 -> R007 | B9: =Restaurants!B8 -> Puneri Misal House | C9: =SUMIFS(Orders!$E$2:$E$301,Orders!$I$2:$I$301,A9,Orders!$D$2:$D$301,"Delivered") -> 5039.07
A10: =Restaurants!A9 -> R008 | B10: =Restaurants!B9 -> Deccan Diner | C10: =SUMIFS(Orders!$E$2:$E$301,Orders!$I$2:$I$301,A10,Orders!$D$2:$D$301,"Delivered") -> 7012.13
A11: =Restaurants!A10 -> R009 | B11: =Restaurants!B10 -> Hyderabadi Biryani House | C11: =SUMIFS(Orders!$E$2:$E$301,Orders!$I$2:$I$301,A11,Orders!$D$2:$D$301,"Delivered") -> 3801.37
A12: =Restaurants!A11 -> R010 | B12: =Restaurants!B11 -> Nizam's Table | C12: =SUMIFS(Orders!$E$2:$E$301,Orders!$I$2:$I$301,A12,Orders!$D$2:$D$301,"Delivered") -> 5962.14
A13: =Restaurants!A12 -> R011 | B13: =Restaurants!B12 -> Gujarat Thali Home | C13: =SUMIFS(Orders!$E$2:$E$301,Orders!$I$2:$I$301,A13,Orders!$D$2:$D$301,"Delivered") -> 7884.63
A14: =Restaurants!A13 -> R012 | B14: =Restaurants!B13 -> Manek Chowk Bites | C14: =SUMIFS(Orders!$E$2:$E$301,Orders!$I$2:$I$301,A14,Orders!$D$2:$D$301,"Delivered") -> 4395.75
... A24: =Restaurants!A23 -> R022 | B24: =Restaurants!B23 -> Park Street Diner | C24: =SUMIFS(Orders!$E$2:$E$301,Orders!$I$2:$I$301,A24,Orders!$D$2:$D$301,"Delivered") -> 2369.21
A25: Total Revenue by Cuisine (Delivered orders)
A26: Cuisine | B26: TotalRevenue
A27: North Indian | B27: =SUMIFS(Orders!$E$2:$E$301,Orders!$K$2:$K$301,A27,Orders!$D$2:$D$301,"Delivered") -> 12567.69
A28: Mughlai | B28: =SUMIFS(Orders!$E$2:$E$301,Orders!$K$2:$K$301,A28,Orders!$D$2:$D$301,"Delivered") -> 24189.42
A29: Street Food | B29: =SUMIFS(Orders!$E$2:$E$301,Orders!$K$2:$K$301,A29,Orders!$D$2:$D$301,"Delivered") -> 22910.64
A30: Seafood | B30: =SUMIFS(Orders!$E$2:$E$301,Orders!$K$2:$K$301,A30,Orders!$D$2:$D$301,"Delivered") -> 16989.23
A31: South Indian | B31: =SUMIFS(Orders!$E$2:$E$301,Orders!$K$2:$K$301,A31,Orders!$D$2:$D$301,"Delivered") -> 10617.49
A32: Multi-Cuisine | B32: =SUMIFS(Orders!$E$2:$E$301,Orders!$K$2:$K$301,A32,Orders!$D$2:$D$301,"Delivered") -> 7635.87
A33: Maharashtrian | B33: =SUMIFS(Orders!$E$2:$E$301,Orders!$K$2:$K$301,A33,Orders!$D$2:$D$301,"Delivered") -> 5039.07
A34: Continental | B34: =SUMIFS(Orders!$E$2:$E$301,Orders!$K$2:$K$301,A34,Orders!$D$2:$D$301,"Delivered") -> 9381.34
A35: Biryani | B35: =SUMIFS(Orders!$E$2:$E$301,Orders!$K$2:$K$301,A35,Orders!$D$2:$D$301,"Delivered") -> 3801.37
A36: Gujarati | B36: =SUMIFS(Orders!$E$2:$E$301,Orders!$K$2:$K$301,A36,Orders!$D$2:$D$301,"Delivered") -> 7884.63
A37: Chettinad | B37: =SUMIFS(Orders!$E$2:$E$301,Orders!$K$2:$K$301,A37,Orders!$D$2:$D$301,"Delivered") -> 5804.12
A38: Kerala | B38: =SUMIFS(Orders!$E$2:$E$301,Orders!$K$2:$K$301,A38,Orders!$D$2:$D$301,"Delivered") -> 4698.4
... A41: Bengali | B41: =SUMIFS(Orders!$E$2:$E$301,Orders!$K$2:$K$301,A41,Orders!$D$2:$D$301,"Delivered") -> 7180.47
A42: Daily Order Volume Trend
A43: OrderDate | B43: OrderCount
A44: 46023 | B44: =COUNTIF(Orders!$C$2:$C$301,A44) -> 5
A45: 46024 | B45: =COUNTIF(Orders!$C$2:$C$301,A45) -> 2
A46: 46025 | B46: =COUNTIF(Orders!$C$2:$C$301,A46) -> 3
A47: 46026 | B47: =COUNTIF(Orders!$C$2:$C$301,A47) -> 6
A48: 46027 | B48: =COUNTIF(Orders!$C$2:$C$301,A48) -> 3
A49: 46028 | B49: =COUNTIF(Orders!$C$2:$C$301,A49) -> 4
A50: 46029 | B50: =COUNTIF(Orders!$C$2:$C$301,A50) -> 1
A51: 46030 | B51: =COUNTIF(Orders!$C$2:$C$301,A51) -> 6
...
